Workbook

Sheet Historical_FS
A1: Section | B1: Item | C1: FY2021 | D1: FY2022 | E1: FY2023 | F1: FY2024 | G1: FY2025
A2: Balance Sheet | B2: Deposits | C2: 2801000452 | D2: 3116841134 | E2: 3630960526 | F2: 4489537451 | G2: 4990551352
B3: Advances | C3: 2521700000 | D3: 3044740000 | E3: 3591070000 | F3: 4303520000 | G3: 4861660000
B4: Investments | C4: 1165650000 | D4: 1159070000 | E4: 1393590000 | F4: 1753020000 | G4: 2028990000
B5: Total Assets | C5: 4788540000 | D5: 5464980000 | E5: 6204300000 | F5: 7676670000 | G5: 8797740000
B6: Total Equity / Net Worth | C6: 844261995 | D6: 966530277 | E6: 1117930264 | F6: 1297723888 | G6: 1574572721
B7: Number of Shares (units) | C7: 1981835668 | D7: 1984661760 | E7: 1985666543 | F7: 1987326015 | G7: 1988096870
B8: Borrowings | C8: 236506455 | D8: 259671169 | E8: 234162684 | F8: 283680956 | G8: 484427559
B9: Cash & Bank Balances | C9: 396265318 | D9: 429239351 | E9: 325423078 | F9: 527884021 | G9: 657791535
B10: Net Debt / (Net Cash) | C10: =C8-C9 -> -159758863 | D10: =D8-D9 -> -169568182 | E10: =E8-E9 -> -91260394 | F10: =F8-F9 -> -244203065 | G10: =G8-G9 -> -173363976
A12: Section | B12: Item | C12: FY2021 | D12: FY2022 | E12: FY2023 | F12: FY2024 | G12: FY2025
A13: Income Statement | B13: Interest Earned | C13: 268402677 | D13: 270388194 | E13: 342508509 | F13: 457989110 | G13: 529197287
B14: Interest Expended | C14: 115006207 | D14: 102209122 | E14: 126989356 | F14: 198057109 | G14: 245779512
B15: Net Interest Income | C15: =C13-C14 -> 153396470 | D15: =D13-D14 -> 168179072 | E15: =E13-E14 -> 215519153 | F15: =F13-F14 -> 259932001 | G15: =G13-G14 -> 283417775
B16: Fee Income | C16: 33840806 | D16: 45547903 | E16: 54400095 | F16: 70490000 | G16: 79440000
B17: Other Non-Interest Income | C17: 20751085 | D17: 18051203 | E17: 16430414 | F17: 32240000 | G17: 70170000
B18: Operating Expenses (Opex) | C18: 85841380 | D18: 111213885 | E18: 137869937 | F18: 166788460 | G18: 187764395
B19: Operating Profit (Pre-Provisions) | C19: =C15+C17+C16-C18 -> 122146981 | D19: =D15+D17+D16-D18 -> 120564293 | E19: =E15+E17+E16-E18 -> 148479725 | F19: =F15+F17+F16-F18 -> 195873541 | G19: =G15+G17+G16-G18 -> 245263380
B20: Provisions & Contingencies | C20: 52498615 | D20: 34781822 | E20: 39086774 | F20: 58058724 | G20: 80763945
B21: Profit Before Tax (PBT) | C21: =C19-C20 -> 69648366 | D21: =D19-D20 -> 85782471 | E21: =E19-E20 -> 109392951 | F21: =F19-F20 -> 137814817 | G21: =G19-G20 -> 164499435
B22: Tax Provision | C22: 23381462 | D22: 27886189 | E22: 34516910 | F22: 42321343 | G22: 51340332
B23: Net Profit (PAT) | C23: 99900000 | D23: 120890000 | E23: 149250000 | F23: 182130000 | G23: 221260000
B25: Earnings Per Share (EPS) | C25: 50.5 | D25: 60.8 | E25: 75 | F25: 91.5 | G25: 111.3
B26: Dividend | C26: 405000 | D26: 2183000 | E26: 2589206 | F26: 3366210 | G26: 3976240
B27: Dividend per Share (DPS) | C27: =C26/C7*1000 -> 0.204356 | D27: =D26/D7*1000 -> 1.0999355 | E27: =E26/E7*1000 -> 1.303948 | F27: =F26/F7*1000 -> 1.6938388 | G27: =G26/G7*1000 -> 2.0000233
A29: Section | B29: Item | C29: FY2021 | D29: FY2022 | E29: FY2023 | F29: FY2024 | G29: FY2025
A30: Key Ratios | B30: Net Interest Margin (NIM) % | C30: 4.5 | D30: 4.7 | E30: 5.4 | F30: 5.3 | G30: 5
B31: Cost to Income Ratio % | C31: 41 | D31: 47 | E31: 48 | F31: 46 | G31: 43
B32: Return on Avg Assets (ROA) % | C32: 2.2 | D32: 2.4 | E32: 2.6 | F32: 2.7 | G32: 2.7
B33: Return on Equity (ROE) % | C33: 12.8 | D33: 13.4 | E33: 14.4 | F33: 15.1 | G33: 15.2
B34: Capital Adequacy Ratio % | C34: 23.4 | D34: 23.7 | E34: 23.3 | F34: 21.8 | G34: 23.3
B35: Tier I Capital Ratio % | C35: 21.4 | D35: 17.6 | E35: 20.8 | F35: 19.2 | G35: 21.1
B36: Gross NPA Ratio % | C36: 3.2 | D36: 2.4 | E36: 2 | F36: 1.4 | G36: 1.5
B37: Net NPA Ratio % | C37: 1.2 | D37: 0.7 | E37: 0.4 | F37: 0.4 | G37: 0.4
A41: Working Notes -
A42: Total Equity / Net Worth equals shareholders' funds (Equity Share Capital + Reserves).
A43: Number of shares is taken from the 'Issued, Subscribed and Paid‑up Equity Share Capital' note. For DCF valuation and EPS we consider only equity shares, because preference shares have a fixed return and do not participate in residual equity value.
A44: Cash balance equals the sum of 'Cash and balances with RBI' and 'Balances with banks'.
A45: Figures in the financial statements are in ₹ thousands(except number of shares which is in units). Dividend per share is computed after converting to ₹ (for example, 405,000 × 1,000 ÷ 1,981,835,668 ≈ ₹0.20 per share).
A46: This sheet compiles five years of standalone financial data (FY21–FY25) sourced from Kotak Mahindra Bank’s annual financial statements.
...

Sheet Valuation
A1: Financial result and Forecast for Kotak Mahindra Bank (Consolidated)
A3: (INR in thousands)
A4: Particulars | B4: Actual | G4: Forecast
B5: FY21 | C5: FY22 | D5: FY23 | E5: FY24 | F5: FY25 | G5: FY26 | H5: FY27 | I5: FY28 | J5: FY29 | K5: FY30
A7: Income Statement
A8: Revenue (Total operating income) | B8: 207988361 | C8: 231778178 | D8: 286349662 | E8: 362662001 | F8: 433027775 | G8: 5.1097277e+08 | H8: 6.0294787e+08 | I8: 7.1147849e+08 | J8: 8.3954462e+08 | K8: 9.9066265e+08
A9: YoY change in % | C9: =(C8-B8)/B8 -> 0.11438052 | D9: =(D8-C8)/C8 -> 0.23544703 | E9: =(E8-D8)/D8 -> 0.26650054 | F9: =(F8-E8)/E8 -> 0.19402577 | G9: =(G8-F8)/F8 -> 0.18 | H9: =(H8-G8)/G8 -> 0.18 | I9: =(I8-H8)/H8 -> 0.18 | J9: =(J8-I8)/I8 -> 0.18 | K9: =(K8-J8)/J8 -> 0.18
A11: Less: OPEX
A12: Operating Expenses | B12: 85841380 | C12: 111213885 | D12: 137869937 | E12: 166788460 | F12: 187764395 | G12: 2.2156199e+08 | H12: 2.5637715e+08 | I12: 2.9654715e+08 | J12: 3.4287174e+08 | K12: 3.9626506e+08
A13: Pre-Provision Operating Profit (PPOP) | B13: =B8-B12 -> 122146981 | C13: =C8-C12 -> 120564293 | D13: =D8-D12 -> 148479725 | E13: =E8-E12 -> 195873541 | F13: =F8-F12 -> 245263380 | G13: =G8-G12 -> 2.8941079e+08 | H13: =H8-H12 -> 3.4657073e+08 | I13: =I8-I12 -> 4.1493134e+08 | ... K13: =K8-K12 -> 5.9439759e+08
A14: YoY change in % (PPOP) | C14: =(C13-B13)/B13 -> -0.012957242 | D14: =(D13-C13)/C13 -> 0.2315398 | E14: =(E13-D13)/D13 -> 0.31919386 | F14: =(F13-E13)/E13 -> 0.25215166 | G14: =(G13-F13)/F13 -> 0.18 | H14: =(H13-G13)/G13 -> 0.19750453 | I14: =(I13-H13)/H13 -> 0.19724865 | J14: =(J13-I13)/I13 -> 0.19700015 | K14: =(K13-J13)/J13 -> 0.19675871
A16: Less: Provisions & Contingencies
A17: Provisions & Contingencies | B17: 52498615 | C17: 34781822 | D17: 39086774 | E17: 58058724 | F17: 80763945 | G17: 91975099 | H17: 1.0853062e+08 | I17: 1.2806613e+08 | J17: 1.5111803e+08 | K17: 1.7831928e+08
A18: Profit Before Tax (PBT) | B18: =B8-B12-B17 -> 69648366 | C18: =C8-C12-C17 -> 85782471 | D18: =D8-D12-D17 -> 109392951 | E18: =E8-E12-E17 -> 137814817 | F18: =F8-F12-F17 -> 164499435 | G18: =G8-G12-G17 -> 1.9743569e+08 | H18: =H8-H12-H17 -> 2.3804011e+08 | I18: =I8-I12-I17 -> 2.8686521e+08 | ... K18: =K8-K12-K17 -> 4.1607831e+08
A19: Less: Tax Provision (historical actuals; ~31% effective assumed for forecasts) | B19: 23381462 | C19: 27886189 | D19: 34516910 | E19: 42321343 | F19: 51340332 | G19: =G18*0.31 -> 61205064 | H19: =H18*0.31 -> 73792435 | I19: =I18*0.31 -> 88928215 | J19: =J18*0.31 -> 1.07122e+08 | K19: =K18*0.31 -> 1.2898428e+08
A20: Earnings After Tax (PAT) | B20: 46266904 | C20: 57896282 | D20: 74876041 | E20: 95493474 | F20: 113159103 | G20: =G18-G19 -> 1.3623063e+08 | H20: =H18-H19 -> 1.6424768e+08 | I20: =I18-I19 -> 1.9793699e+08 | J20: =J18-J19 -> 2.3843284e+08 | K20: =K18-K19 -> 2.8709404e+08
A21: Add: Provision and Contigencies | B21: =B17 -> 52498615 | C21: =C17 -> 34781822 | D21: =D17 -> 39086774 | E21: =E17 -> 58058724 | F21: =F17 -> 80763945 | G21: =G17 -> 91975099 | H21: =H17 -> 1.0853062e+08 | I21: =I17 -> 1.2806613e+08 | ... K21: =K17 -> 1.7831928e+08
A22: Free Cash Flow to Equity (FCFE) | B22: =SUM(B20:B21) -> 98765519 | C22: =SUM(C20:C21) -> 92678104 | D22: =SUM(D20:D21) -> 113962815 | E22: =SUM(E20:E21) -> 153552198 | F22: =SUM(F20:F21) -> 193923048 | G22: =SUM(G20:G21) -> 2.2820572e+08 | H22: =SUM(H20:H21) -> 2.7277829e+08 | I22: =SUM(I20:I21) -> 3.2600312e+08 | ... K22: =SUM(K20:K21) -> 4.6541331e+08
A24: Discount rate (Cost of Equity / WACC) | B24: =WACC!B18 -> 0.1075
A25: Terminal growth rate (g) | B25: 0.05
A26: PV of FCFE @ discount rate | G26: =G22/(1+B24)^1 -> 2.0605483e+08 | H26: =H22/(1+B24)^2 -> 2.2239363e+08 | I26: =I22/(1+B24)^3 -> 2.3998857e+08 | J26: =J22/(1+B24)^4 -> 2.589341e+08 | K26: =K22/(1+B24)^5 -> 2.7933164e+08
A27: Present Value of Terminal Value (PV_TV) | B27: =(K22*(1+$B$25)/($B$24-$B$25))/(1+$B$24)^5 -> 5.1008386e+09
A28: Cumulative PV of FCFE over explicit forecast period | B28: =SUM(G26:K26) -> 1.2067028e+09
A29: Enterprise Value | B29: =B28+B27 -> 6.3075414e+09
A31: Equity value per share (₹) | B31: =B29*1000/F39 -> 3172.6529
A33: Balance Sheet Items
A35: Total Assets | B35: 1050991877 | C35: 1005802168 | D35: 1214037287 | E35: 1554037587 | F35: 1819074474 | G35: 2.0919356e+09 | H35: 2.405726e+09 | I35: 2.7665849e+09 | J35: 3.1815726e+09 | K35: 3.6588085e+09
A36: Deposits | B36: 2801000452 | C36: 3116841134 | D36: 3630960526 | E36: 4489537451 | F36: 4990551352 | G36: 5.7890396e+09 | H36: 6.7152859e+09 | I36: 7.7897316e+09 | J36: 9.0360887e+09 | K36: 1.0481863e+10
A37: Advances | B37: 2236886221 | C37: 2712536018 | D37: 3198612074 | E37: 3760752659 | F37: 4269092008 | G37: 4.9948376e+09 | H37: 5.84396e+09 | I37: 6.8374333e+09 | J37: 7.9997969e+09 | K37: 9.3597624e+09
A38: Total Equity / Net Worth | B38: =Historical_FS!C6 -> 844261995 | C38: =Historical_FS!D6 -> 966530277 | D38: =Historical_FS!E6 -> 1117930264 | E38: =Historical_FS!F6 -> 1297723888 | F38: =Historical_FS!G6 -> 1574572721 | G38: =F38 -> 1574572721 | H38: =F38 -> 1574572721 | I38: =F38 -> 1574572721 | J38: =F38 -> 1574572721 | K38: =F38 -> 1574572721
A39: No. of Shares (units) | B39: =Historical_FS!C7 -> 1981835668 | C39: =Historical_FS!D7 -> 1984661760 | D39: =Historical_FS!E7 -> 1985666543 | E39: =Historical_FS!F7 -> 1987326015 | F39: =Historical_FS!G7 -> 1988096870 | G39: =F39 -> 1988096870 | H39: =F39 -> 1988096870 | I39: =F39 -> 1988096870 | J39: =F39 -> 1988096870 | K39: =F39 -> 1988096870
A40: ROE (PAT / Equity) | B40: =B20/B38 -> 0.054801595 | C40: =C20/C38 -> 0.059901157 | D40: =D20/D38 -> 0.066977381 | E40: =E20/E38 -> 0.073585356 | F40: =F20/F38 -> 0.071866546 | G40: =G20/G38 -> 0.086519107 | H40: =H20/H38 -> 0.10431254 | I40: =I20/I38 -> 0.12570839 | ... K40: =K20/K38 -> 0.18233139
A41: ROA (PAT / Total Assets) | B41: =B20/B35 -> 0.044022133 | C41: =C20/C35 -> 0.057562296 | D41: =D20/D35 -> 0.06167524 | E41: =E20/E35 -> 0.061448626 | F41: =F20/F35 -> 0.062206965 | G41: =G20/G35 -> 0.065121805 | H41: =H20/H35 -> 0.068273643 | I41: =I20/I35 -> 0.071545607 | ... K41: =K20/K35 -> 0.078466538

Sheet WACC
A1: Cost of Equity / WACC – CAPM Approach for Kotak Mahindra Bank (Consolidated)
A3: All rates are annual; values as of late 2025 based on publicly available market data.
A5: Input | B5: Value | C5: Notes
A6: Risk-free rate (Rf) – India 10Y G-Sec | B6: 0.0655 | C6: Approx. 6.5–6.6% based on India 10Y G-Sec yields around 6.53–6.57% (CCIL; Macromicro India 10Y).
A7: Equity risk premium (ERP) – India | B7: 0.07 | C7: Midpoint of Indian ERP estimates ~6.8% (Incwert) and academic range 6–11%; 7% used.
A9: Beta estimates (levered, equity)
A10: Source | B10: Beta | C10: NOTES
A11: Yahoo Finance – KOTAKBANK.NS (5Y monthly) | B11: 0.19 | C11: Very low historical beta; low co-movement with index.
A12: Moneycontrol – Kotak Bank (Beta) | B12: 1 | C12: Moneycontrol shows beta ~1.0–1.03 vs market.
A13: Average of above betas | B13: =AVERAGE(B11:B12) -> 0.595 | C13: Simple average of Yahoo and Moneycontrol.
A14: Chosen beta for valuation (β) | B14: 0.6 | C14: Rounded near average, consistent with research that Kotak is low-beta vs peers.
A16: Cost of Equity (Ke) using CAPM
A17: Formula: | B17: Ke = Rf + β × ERP
A18: Computed Ke | B18: =B6 + B14*B7 -> 0.1075 | C18: Discount rate used in FCFE DCF valuation.
A22: Sensitivity of Cost of Equity to Beta
A23: Beta | B23: Ke
A24: 0.5 | B24: =$B$6 + A24*$B$7 -> 0.1005
A25: 0.6 | B25: =$B$6 + A25*$B$7 -> 0.1075
A26: 0.8 | B26: =$B$6 + A26*$B$7 -> 0.1215
A28: Working Notes
A29: Beta measures how volatile Kotak’s stock is compared to the market (systematic risk). A beta of 1 means the stock moves in line with the market; beta below 1 implies lower volatility.
A30: The base cost of equity of 10.75% represents the return equity investors require for holding Kotak’s shares. If the bank’s realised return is below this rate, the stock would not be attractive on a risk‑adjusted basis.
A31: For banks, valuation generally uses Cost of Equity as discount rate; deposits are operating liabilities, not financing capital. Thus WACC ≈ Ke.

Sheet Price to Book Analysis
A1: Relative Valuation – Peer P/B Comparison and Blended Fair Value
A3: Peer P/B comparison (Price-to-Book)
A5: Bank | B5: P/B (x)
A6: HDFC Bank | B6: 2.98
A7: ICICI Bank | B7: 3.19
A8: Axis Bank | B8: 2.13
A9: IndusInd Bank | B9: 1.02
A10: State Bank of India | B10: 1.86
A11: Peer median P/B (x) | B11: =MEDIAN(B6:B10) -> 2.13
A13: Kotak multiples-based valuation (P/B method)
A14: Kotak Book Value per share FY25 (₹) | B14: =Historical_FS!G6*1000/Historical_FS!G7 -> 792
A15: Peer median P/B applied to Kotak | B15: =B11 -> 2.13
A16: Fair value per share from P/B multiples (₹) | B16: =B14*B15 -> 1686.96
A17: Current market price (₹) | B17: 2147.75
A18: Upside / (Downside) vs current price | B18: =(B16-B17)/B17 -> -0.21454545 | C18: The Upside/(Downside) vs Current Price shows how much room there is for price movement relative to the estimated fair value.
C19: In this case, Kotak’s P/B-based fair value is about ₹1,687 per share, while the current market price is around ₹2,148 — roughly 21.5% higher.
C20: That indicates Kotak Mahindra Bank is overvalued on a relative basis compared to peers.
A21: Blended Valuation – Kotak Mahindra Bank | C21: Unless there’s strong growth ahead to justify this premium, the stock could face downside pressure toward its fair value.”
B23: DCF | C23: Multiples
A24: Est. Price (₹ per share) | B24: =Valuation!B31 -> 3172.6529 | C24: =B16 -> 1686.96
A25: Weights | B25: 0.4 | C25: 0.6
A26: Blended Fair Value (₹ per share) | B26: =B24*B25+C24*C25 -> 2281.2372
A27: Working Notes
A28: • The DCF method gives an intrinsic value of ₹3172.65 per share based on long‑term cash flows, while the P/B multiples method gives ₹1,686.96 per share using the peer median P/B of 2.13× and Kotak’s FY25 book value per share of about ₹792.00
A30: • The blended fair value of ₹2281.24 per share (40% DCF, 60% multiples) suggests that one should buy the shares of Kotak Mahindra bank
A31: We chose the median peer P/B multiple because it provides a more representative and reliable benchmark of sector valuation by minimizing the impact of outliers, ensuring that extreme high or low valuations of individual banks do not distort Kotak Mahindra Bank’s fair value estimate.

Sheet Charts
A1: Year | B1: Actual Revenue | C1: Forecast Revenue
A2: FY21 | B2: =Valuation!B8 -> 207988361
A3: FY22 | B3: =Valuation!C8 -> 231778178
A4: FY23 | B4: =Valuation!D8 -> 286349662
A5: FY24 | B5: =Valuation!E8 -> 362662001
A6: FY25 | B6: =Valuation!F8 -> 433027775
A7: FY26 | C7: =Valuation!G8 -> 5.1097277e+08
A8: FY27 | C8: =Valuation!H8 -> 6.0294787e+08
A9: FY28 | C9: =Valuation!I8 -> 7.1147849e+08
A10: FY29 | C10: =Valuation!J8 -> 8.3954462e+08
A11: FY30 | C11: =Valuation!K8 -> 9.9066265e+08
A20: Year | B20: Free Cash Flow to Equity (FCFE)
A21: FY26 | B21: =Valuation!G22 -> 2.2820572e+08
A22: FY27 | B22: =Valuation!H22 -> 2.7277829e+08
A23: FY28 | B23: =Valuation!I22 -> 3.2600312e+08
A24: FY29 | B24: =Valuation!J22 -> 3.8955087e+08
A25: FY30 | B25: =Valuation!K22 -> 4.6541331e+08

Sheet subsidiaries name
A1: Subsidiaries
A2: Kotak Mahindra Prime Limited
A3: Kotak Securities Limited
A4: Kotak Mahindra Capital Company Limited
A5: Kotak Mahindra Life Insurance Company Limited
A6: Kotak Mahindra General Insurance Company Limited
A7: Kotak Mahindra Investments Limited
A8: Kotak Mahindra Asset Management Company Limited
A9: Kotak Mahindra Trustee Company Limited
A10: Kotak Mahindra (International) Limited
A11: Kotak Mahindra (UK) Limited
A12: Kotak Mahindra, Inc
... A20: BSS Microfinance Limited

Sheet Summary
A1: Corporate Finance – Individual Assignment 2
A2: Kotak Mahindra Bank (Consolidated) – Equity Valuation Summary (DCF & Relative)
A4: Valuation Overview
A6: Method | B6: Fair Value (₹/share) | C6: Weight | D6: Contribution | E6: Key Inputs
A7: DCF (FCFE) | B7: =Valuation!B31 -> 3172.6529 | C7: 0.4 | D7: =B7*C7 -> 1269.0612 | E7: Risk-free rate (Rf) | F7: =WACC!B6 -> 0.0655
A8: Relative (P/B multiples) | B8: ='Price to Book Analysis'!B16 -> 1686.96 | C8: 0.6 | D8: =B8*C8 -> 1012.176 | E8: Equity risk premium (ERP) | F8: =WACC!B7 -> 0.07
A9: Blended fair value | B9: =D7+D8 -> 2281.2372 | E9: Beta (β) | F9: =WACC!B14 -> 0.6
E10: Cost of Equity / WACC | F10: =WACC!B18 -> 0.1075
A11: Current market price (₹) | B11: ='Price to Book Analysis'!B17 -> 2147.75 | E11: Terminal growth (g) | F11: =Valuation!B25 -> 0.05
A12: Upside / (Downside) vs current price | B12: =(B9-B11)/B11 -> 0.0621521

Sheet Notes
A1: Notes
A2: Sensitivity Analysis – DCF Fair Value per Share | E2: No. of Shares (units) | F2: =Valuation!K39 -> 1988096870
A3: Terminal Growth (g) | B3: WACC 10.0% | C3: WACC 10.75% (Base) | D3: WACC 11.5% | E3: WACC 12.0%
A4: 4.0% | B4: =($G$13 + (Valuation!$K$22*(1+$A4)/(0.1-$A4))/(1+0.1)^5)*1000/$F$2 -> 3139.6634 | C4: =($G$14 + (Valuation!$K$22*(1+$A4)/(0.1075-$A4))/(1+0.1075)^5)*1000/$F$2 -> 2771.7357 | D4: =($G$15 + (Valuation!$K$22*(1+$A4)/(0.115-$A4))/(1+0.115)^5)*1000/$F$2 -> 2477.8606 | E4: =($G$16 + (Valuation!$K$22*(1+$A4)/(0.12-$A4))/(1+0.12)^5)*1000/$F$2 -> 2312.7916
A5: 4.5% | B5: =($G$13 + (Valuation!$K$22*(1+$A5)/(0.1-$A5))/(1+0.1)^5)*1000/$F$2 -> 3381.9262 | C5: =($G$14 + (Valuation!$K$22*(1+$A5)/(0.1075-$A5))/(1+0.1075)^5)*1000/$F$2 -> 2956.1576 | D5: =($G$15 + (Valuation!$K$22*(1+$A5)/(0.115-$A5))/(1+0.115)^5)*1000/$F$2 -> 2622.1095 | E5: =($G$16 + (Valuation!$K$22*(1+$A5)/(0.12-$A5))/(1+0.12)^5)*1000/$F$2 -> 2436.7705
A6: 5.0% | B6: =($G$13 + (Valuation!$K$22*(1+$A6)/(0.1-$A6))/(1+0.1)^5)*1000/$F$2 -> 3672.6414 | C6: =($G$14 + (Valuation!$K$22*(1+$A6)/(0.1075-$A6))/(1+0.1075)^5)*1000/$F$2 -> 3172.6529 | D6: =($G$15 + (Valuation!$K$22*(1+$A6)/(0.115-$A6))/(1+0.115)^5)*1000/$F$2 -> 2788.5506 | E6: =($G$16 + (Valuation!$K$22*(1+$A6)/(0.12-$A6))/(1+0.12)^5)*1000/$F$2 -> 2578.4607
A7: 5.5% | B7: =($G$13 + (Valuation!$K$22*(1+$A7)/(0.1-$A7))/(1+0.1)^5)*1000/$F$2 -> 4027.9601 | C7: =($G$14 + (Valuation!$K$22*(1+$A7)/(0.1075-$A7))/(1+0.1075)^5)*1000/$F$2 -> 3430.3854 | D7: =($G$15 + (Valuation!$K$22*(1+$A7)/(0.115-$A7))/(1+0.115)^5)*1000/$F$2 -> 2982.7318 | E7: =($G$16 + (Valuation!$K$22*(1+$A7)/(0.12-$A7))/(1+0.12)^5)*1000/$F$2 -> 2741.9494
A8: 6.0% | B8: =($G$13 + (Valuation!$K$22*(1+$A8)/(0.1-$A8))/(1+0.1)^5)*1000/$F$2 -> 4472.1084 | C8: =($G$14 + (Valuation!$K$22*(1+$A8)/(0.1075-$A8))/(1+0.1075)^5)*1000/$F$2 -> 3742.3774 | D8: =($G$15 + (Valuation!$K$22*(1+$A8)/(0.115-$A8))/(1+0.115)^5)*1000/$F$2 -> 3212.2187 | E8: =($G$16 + (Valuation!$K$22*(1+$A8)/(0.12-$A8))/(1+0.12)^5)*1000/$F$2 -> 2932.6863
A11: Year | B11: FY26 | C11: FY27 | D11: FY28 | E11: FY29 | F11: FY30 | G11: Cumulative PV of FCFE
A12: Free Future Cashflow (FCFE) | B12: =Valuation!G22 -> 2.2820572e+08 | C12: =Valuation!H22 -> 2.7277829e+08 | D12: =Valuation!I22 -> 3.2600312e+08 | E12: =Valuation!J22 -> 3.8955087e+08 | F12: =Valuation!K22 -> 4.6541331e+08
A13: 0.1 | B13: =B12/(1+0.1)^1 -> 2.0745975e+08 | C13: =C12/(1+0.1)^2 -> 2.2543661e+08 | D13: =D12/(1+0.1)^3 -> 2.4493097e+08 | E13: =E12/(1+0.1)^4 -> 2.6606849e+08 | F13: =F12/(1+0.1)^5 -> 2.8898505e+08 | G13: =B13+C13+D13+E13+F13 -> 1.2328809e+09
A14: 0.1075 | B14: =B12/(1+0.1075)^1 -> 2.0605483e+08 | C14: =C12/(1+0.1075)^2 -> 2.2239363e+08 | D14: =D12/(1+0.1075)^3 -> 2.3998857e+08 | E14: =E12/(1+0.1075)^4 -> 2.589341e+08 | F14: =F12/(1+0.1075)^5 -> 2.7933164e+08 | G14: =B14+C14+D14+E14+F14 -> 1.2067028e+09
A15: 0.115 | B15: =B12/(1+0.115)^1 -> 2.0466881e+08 | C15: =C12/(1+0.115)^2 -> 2.1941185e+08 | D15: =D12/(1+0.115)^3 -> 2.3517825e+08 | E15: =E12/(1+0.115)^4 -> 2.5203724e+08 | F15: =F12/(1+0.115)^5 -> 2.7006261e+08 | G15: =B15+C15+D15+E15+F15 -> 1.1813588e+09
A16: 0.12 | B16: =B12/(1+0.12)^1 -> 2.0375511e+08 | C16: =C12/(1+0.12)^2 -> 2.1745719e+08 | D16: =D12/(1+0.12)^3 -> 2.3204258e+08 | E16: =E12/(1+0.12)^4 -> 2.4756662e+08 | F16: =F12/(1+0.12)^5 -> 2.6408801e+08 | G16: =B16+C16+D16+E16+F16 -> 1.1649095e+09
A19: Working Notes
A20: Total Equity / Net Worth in Valuation is directly linked to Historical_FS (₹ in thousands).
A21: Number of shares is directly linked toHistorical_FS row 7 and held constant at the FY2025 level for FY2026–FY2030.
A22: Rationale: Kotak has not indicated large equity issuance or buybacks, so assuming a stable share count isolates valuation changes to earnings and discount rate.
A23: DCF fair value per share = Total equity value from FCFE DCF (₹ in thousands) × 1,000 ÷ number of shares (units).
A24: Book value per share is based on FY2025 equity and shares fHistorical_FS to ensure consistency with the DCF.
A25: Terminal growth- As we see companies continue for indefinite period and we usually do DCF for merely 5-7 years so we bring In terminal growth for more years,
A26: So I took range from 4% to 6% for terminal growth which represents long-term sustainable growth for India which is also equal to GDP growth rate(5-6%)
A27: Each cell in the sensitivity table above should show a fair value per share computed from the DCF.
A28: For any WACC–g combination, the equity value per share is calculated as:
A29: Equity value per share = (PV of FCFE for FY26–FY30 + PV of Terminal Value) ÷ Number of shares.
A30: PV of FCFE comes from the discounted FCFE row below for the chosen WACC, and PV of Terminal Value is recomputed for each WACC–g pair using the Gordon growth formula.
... A35: This approach ensures my valuation remains realistic and robust under slightly different market conditions
A37: WACC | B37: Meaning
A38: 0.1 | B38: Optimistic scenario → Investors expect a lower return → Kotak’s value appears higher
A39: 0.1075 | B39: Base case → Derived from CAPM (6.55% + 0.6×7%)
A40: 0.115 | B40: Slightly higher risk scenario
A41: 0.12 | B41: High-risk scenario → Investors demand more return → Kotak’s value appears lower
A42: Money today is worth more than money in the future.
A43: If Kotak will earn ₹100 crores next year, that’s not worth ₹100 crores today —
A44: because we could invest that ₹100 crores elsewhere and earn a return.
A45: So, we bring future money back to today’s value using a “discount factor.”
A46: That’s what WACC does — it tells you how much to discount.

Sheet References
A1: References
A3: Category | B3: URL
A4: Growth – Profit | B4: https://www.screener.in/company/KOTAKBANK/consolidated/
A5: Growth – Revenue | B5: https://finbox.com/BSE%3A500247/explorer/total_rev_cagr_5y/
A6: Growth – Operating Income | B6: https://finbox.com/NSEI%3AKOTAKBANK/explorer/oper_inc_cagr_5y/
A7: Growth – Net Income Forecast | B7: https://www.alphaspread.com/security/nse/kotakbank/analyst-estimates
A8: Growth – Credit & NII | B8: https://bfsi.economictimes.indiatimes.com/articles/kotak-mahindra-banks-powerful-growth-strategy-aiming-for-a-17-cagr-in-advances-and-nii-by-fy28/122848662
A9: Growth – Loans & Deposits Recent | B9: https://www.alphaspread.com/security/nse/kotakbank/investor-relations
A10: HDFC Bank P/B multiple | B10: https://www.screener.in/company/HDFCBANK/
A11: ICICI Bank P/B multiple | B11: https://www.screener.in/company/ICICIBANK/
A12: Axis Bank P/B multiple | B12: https://www.screener.in/company/AXISBANK/
A13: IndusInd Bank P/B multiple | B13: https://www.screener.in/company/INDUSINDBK/
A14: State Bank of India P/B multiple | B14: https://www.screener.in/company/SBIN/
... A19: Beta – Moneycontrol | B19: https://www.moneycontrol.com/india/stockpricequote/banks-private-sector/kotakmahindrabank/KMB
